<?xml version="1.0" ?>
<robot name="ur">
  <!-- Add URDF transmission elements (for ros_control) -->
  <!--<xacro:ur_arm_transmission prefix="${prefix}" hw_interface="${transmission_hw_interface}" />-->
  <!-- Placeholder for ros2_control transmission which don't yet exist -->
  <!-- links -  main serial chain -->
  <link name="base_link"/>
  <joint name="base_link-pod_base_link" type="fixed">
    <parent link="base_link"/>
    <child link="pod_base_link"/>
    <origin rpy="0 0 0" xyz="0.0 0 0"/>
  </joint>

  <link name="pod_base_link">
    <!-- <visual>
      <origin rpy="3.14 0 1.57" xyz="0.305 0.065 0.517"/>
      <geometry>
        <mesh filename="meshes/pod/untitled.dae"/>
      </geometry>
    </visual> -->
    <!-- <collision>
      <origin rpy="-1.57 0 1.57" xyz="0.305 0.065 0.517"/>
      <geometry>
        <mesh filename="meshes/pod/untitled.dae"/>
      </geometry>
    </collision> -->
  </link>
  
  <joint name="base_link-base_link_inertia" type="fixed">
    <parent link="base_link"/>
    <child link="base_link_inertia"/>
    <!-- 'base_link' is REP-103 aligned (so X+ forward), while the internal
           frames of the robot/controller have X+ pointing backwards.
           Use the joint between 'base_link' and 'base_link_inertia' (a dummy
           link/frame) to introduce the necessary rotation over Z (of pi rad).
      -->
    <origin rpy="0 0 3.141592653589793" xyz="-0.05 -0.05 0.05"/>
  </joint>
  <link name="base_link_inertia">
    <visual>
      <origin rpy="0 0 3.141592653589793" xyz="0 0 0"/>
      <geometry>
        <mesh filename="meshes/ur10e/visual/base.dae"/>
      </geometry>
    </visual>
    <collision>
      <origin rpy="0 0 3.141592653589793" xyz="0 0 0"/>
      <geometry>
        <mesh filename="meshes/ur10e/collision/base.stl"/>
      </geometry>
    </collision>
    <inertial>
      <mass value="4.0"/>
      <origin rpy="0 0 0" xyz="0 0 0"/>
      <inertia ixx="0.0061063308908" ixy="0.0" ixz="0.0" iyy="0.0061063308908" iyz="0.0" izz="0.01125"/>
    </inertial>
  </link>
  <joint name="shoulder_pan_joint" type="revolute">
    <parent link="base_link_inertia"/>
    <child link="shoulder_link"/>
    <origin rpy="0 0 0" xyz="0 0 0.1807"/>
    <axis xyz="0 0 1"/>
    <limit effort="330.0" lower="-6.283185307179586" upper="6.283185307179586" velocity="2.0943951023931953"/>
    <dynamics damping="0" friction="0"/>
  </joint>
  <link name="shoulder_link">
    <visual>
      <origin rpy="0 0 3.141592653589793" xyz="0 0 0"/>
      <geometry>
        <mesh filename="meshes/ur10e/visual/shoulder.dae"/>
      </geometry>
    </visual>
    <collision>
      <origin rpy="0 0 3.141592653589793" xyz="0 0 0"/>
      <geometry>
        <mesh filename="meshes/ur10e/collision/shoulder.stl"/>
      </geometry>
    </collision>
    <inertial>
      <mass value="7.369"/>
      <origin rpy="0 0 0" xyz="0 0 0"/>
      <inertia ixx="0.029819260655624295" ixy="0.0" ixz="0.0" iyy="0.029819260655624295" iyz="0.0" izz="0.020725312499999995"/>
    </inertial>
  </link>
  <joint name="shoulder_lift_joint" type="revolute">
    <parent link="shoulder_link"/>
    <child link="upper_arm_link"/>
    <origin rpy="1.570796327 0 0" xyz="0 0 0"/>
    <axis xyz="0 0 1"/>
    <limit effort="330.0" lower="-6.283185307179586" upper="6.283185307179586" velocity="2.0943951023931953"/>
    <dynamics damping="0" friction="0"/>
  </joint>
  <link name="upper_arm_link">
    <visual>
      <origin rpy="1.5707963267948966 0 -1.5707963267948966" xyz="0 0 0.176"/>
      <geometry>
        <mesh filename="meshes/ur16e/visual/upperarm.dae"/>
      </geometry>
    </visual>
    <collision>
      <origin rpy="1.5707963267948966 0 -1.5707963267948966" xyz="0 0 0.176"/>
      <geometry>
        <mesh filename="meshes/ur16e/collision/upperarm.stl"/>
      </geometry>
    </collision>
    <inertial>
      <mass value="10.45"/>
      <origin rpy="0 1.5707963267948966 0" xyz="-0.2392 0.0 0.175"/>
      <inertia ixx="0.21399985623335657" ixy="0.0" ixz="0.0" iyy="0.21399985623335657" iyz="0.0" izz="0.029390624999999997"/>
    </inertial>
  </link>
  <joint name="elbow_joint" type="revolute">
    <parent link="upper_arm_link"/>
    <child link="forearm_link"/>
    <origin rpy="0 0 0" xyz="-0.4784 0 0"/>
    <axis xyz="0 0 1"/>
    <limit effort="150.0" lower="-6.283185307179586" upper="6.283185307179586" velocity="3.141592653589793"/>
    <dynamics damping="0" friction="0"/>
  </joint>
  <link name="forearm_link">
    <visual>
      <origin rpy="1.5707963267948966 0 -1.5707963267948966" xyz="0 0 0.04"/>
      <geometry>
        <mesh filename="meshes/ur16e/visual/forearm.dae"/>
      </geometry>
    </visual>
    <collision>
      <origin rpy="1.5707963267948966 0 -1.5707963267948966" xyz="0 0 0.04"/>
      <geometry>
        <mesh filename="meshes/ur16e/collision/forearm.stl"/>
      </geometry>
    </collision>
    <inertial>
      <mass value="4.321"/>
      <origin rpy="0 1.5707963267948966 0" xyz="-0.18 0.0 0.04"/>
      <inertia ixx="0.052743185152717496" ixy="0.0" ixz="0.0" iyy="0.052743185152717496" iyz="0.0" izz="0.012152812499999997"/>
    </inertial>
  </link>
  <joint name="wrist_1_joint" type="revolute">
    <parent link="forearm_link"/>
    <child link="wrist_1_link"/>
    <origin rpy="0 0 0" xyz="-0.36 0 0.17415"/>
    <axis xyz="0 0 1"/>
    <limit effort="56.0" lower="-6.283185307179586" upper="6.283185307179586" velocity="3.141592653589793"/>
    <dynamics damping="0" friction="0"/>
  </joint>
  <link name="wrist_1_link">
    <visual>
      <origin rpy="1.5707963267948966 0 0" xyz="0 0 -0.135"/>
      <geometry>
        <mesh filename="meshes/ur10e/visual/wrist1.dae"/>
      </geometry>
    </visual>
    <collision>
      <origin rpy="1.5707963267948966 0 0" xyz="0 0 -0.135"/>
      <geometry>
        <mesh filename="meshes/ur10e/collision/wrist1.stl"/>
      </geometry>
    </collision>
    <inertial>
      <mass value="2.18"/>
      <origin rpy="0 0 0" xyz="0 0 0"/>
      <inertia ixx="0.0056816227273499996" ixy="0.0" ixz="0.0" iyy="0.0056816227273499996" iyz="0.0" izz="0.00613125"/>
    </inertial>
  </link>
  <joint name="wrist_2_joint" type="revolute">
    <parent link="wrist_1_link"/>
    <child link="wrist_2_link"/>
    <origin rpy="1.570796327 0 0" xyz="0 -0.11985 -2.458164590756244e-11"/>
    <axis xyz="0 0 1"/>
    <limit effort="56.0" lower="-6.283185307179586" upper="6.283185307179586" velocity="3.141592653589793"/>
    <dynamics damping="0" friction="0"/>
  </joint>
  <link name="wrist_2_link">
    <visual>
      <origin rpy="0 0 0" xyz="0 0 -0.12"/>
      <geometry>
        <mesh filename="meshes/ur10e/visual/wrist2.dae"/>
      </geometry>
    </visual>
    <collision>
      <origin rpy="0 0 0" xyz="0 0 -0.12"/>
      <geometry>
        <mesh filename="meshes/ur10e/collision/wrist2.stl"/>
      </geometry>
    </collision>
    <inertial>
      <mass value="2.033"/>
      <origin rpy="0 0 0" xyz="0 0 0"/>
      <inertia ixx="0.0052985041305975" ixy="0.0" ixz="0.0" iyy="0.0052985041305975" iyz="0.0" izz="0.0057178125"/>
    </inertial>
  </link>
  <joint name="wrist_3_joint" type="revolute">
    <parent link="wrist_2_link"/>
    <child link="wrist_3_link"/>
    <origin rpy="1.570796326589793 3.141592653589793 3.141592653589793" xyz="0 0.11655 -2.390480459346185e-11"/>
    <axis xyz="0 0 1"/>
    <limit effort="56.0" lower="-6.283185307179586" upper="6.283185307179586" velocity="3.141592653589793"/>
    <dynamics damping="0" friction="0"/>
  </joint>
  <link name="wrist_3_link">
    <visual>
      <origin rpy="1.5707963267948966 0 0" xyz="0 0 -0.1168"/>
      <geometry>
        <mesh filename="meshes/ur10e/visual/wrist3.dae"/>
      </geometry>
    </visual>
    <collision>
      <origin rpy="1.5707963267948966 0 0" xyz="0 0 -0.1168"/>
      <geometry>
        <mesh filename="meshes/ur10e/collision/wrist3.stl"/>
      </geometry>
    </collision>
    <inertial>
      <mass value="0.907"/>
      <origin rpy="0 0 0" xyz="0.0 0.0 -0.025"/>
      <inertia ixx="0.0006481268240825001" ixy="0.0" ixz="0.0" iyy="0.0006481268240825001" iyz="0.0" izz="0.0009183374999999999"/>
    </inertial>
  </link>

  <joint name="sensor_1_joint" type="fixed">
    <parent link="wrist_3_link"/>
    <child link="sensor_1_link"/>
    <origin rpy="0 0 0" xyz="0.0323088 0 0.0768096"/>
  </joint>

  <joint name="sensor_2_joint" type="fixed">
    <parent link="wrist_3_link"/>
    <child link="sensor_2_link"/>
    <origin rpy="0 0 0" xyz="-0.0323088 0 0.0768096"/>
  </joint>
  
  <link name="sensor_1_link">
    <visual>
      <geometry>
        <cylinder length="0.01" radius="0.01"/>
      </geometry>
      <color rgba="1 1 1 1"/>
    </visual>
  </link>
  <link name="sensor_2_link">
    <visual>
      <geometry>
        <cylinder length="0.01" radius="0.01"/>
      </geometry>
      <color rgba="1 1 1 1"/>
    </visual>
  </link>
  
  <joint name="rod_joint" type="fixed">
    <parent link="wrist_3_link"/>
    <child link="ee_link"/>
    <origin rpy="0 -1.57 0" xyz="0 0 0.0"/>
  </joint>
  
  <link name="ee_link"/>
  
</robot>